<sdf version="1.4">
    <model name='dd_robot'>
    <link name='chassis'>
        <pose>0 0 0.1 0 0 0</pose>
        <static>true</static>
        <collision name='collision'>
            <geometry>
                <box>
                    <size> 0.4 0.2 0.1 </size>
                </box>
            </geometry>
        </collision>
        <visual name='visual'>
            <geometry>
                <box>
                    <size> 0.4 0.2 0.1 </size>
                </box>
            </geometry>
        </visual>


        <!-- Caster wheel -->
        <collision name='caster_collision'>
            <pose>-0.15 0 -0.05 0 0 0 </pose>
            <geometry>
                <sphere>
                    <radius>0.05</radius>
                </sphere>
            </geometry>

            <surface>
                <friction>
                    <ode>
                        <mu>0</mu>
                        <mu2>0</mu2>
                        <slip1>1.0</slip1>
                        <slip2>1.0</slip2>
                    </ode>
                </friction>
            </surface>

        </collision>
        <visual name='caster_visual'>
            <pose>-0.15 0 -0.05 0 0 0 </pose>
            <geometry>
                <sphere>
                    <radius>0.05</radius>
                </sphere>
            </geometry>
        </visual>
        </link>

        <!-- Left Wheel -->
        <link name='left_wheel'>
            <pose>0.1 0.13 0.1 0 1.5707 1.5707</pose>
            <collision name='lw_collision'>
                <geometry>
                    <cylinder>
                        <radius>0.1</radius>
                        <length>0.05</length>
                    </cylinder>
                </geometry>
            </collision>
            <visual name='lw_visual'>
                <geometry>
                    <cylinder>
                        <radius>0.1</radius>
                        <length>0.05</length>
                    </cylinder>
                </geometry>
            </visual>
        </link>


        <!-- Left Wheel -->
        <link name='right_wheel'>
            <pose>0.1 -0.13 0.1 0 1.5707 1.5707</pose>
            <collision name='lw_collision'>
                <geometry>
                    <cylinder>
                        <radius>0.1</radius>
                        <length>0.05</length>
                    </cylinder>
                </geometry>
            </collision>
            <visual name='lw_visual'>
                <geometry>
                    <cylinder>
                        <radius>0.1</radius>
                        <length>0.05</length>
                    </cylinder>
                </geometry>
            </visual>
        </link>

        <joint type='revolute' name='left_wheel_hinge'>
            <pose> 0 0 -0.03 0 0 0 </pose>
            <child>left_wheel</child>
            <parent>chassis</parent>
            <axis>
                <xyz>0 1 0</xyz>
            </axis>
        </joint>

         <joint type='revolute' name='right_wheel_hinge'>
            <pose> 0 0 0.03 0 0 0 </pose>
            <child>right_wheel</child>
            <parent>chassis</parent>
            <axis>
                <xyz>0 1 0</xyz>
            </axis>
        </joint>




     



<!--
	<plugin name="set_speed_joint_plugin" filename="libset_speed_joint_plugin.so">
		<namespace_model>dd_robot</namespace_model>
		<activate_pid_control>yes</activate_pid_control>                
		<wheel_kp>0.1</wheel_kp>
		<wheel_ki>0.0</wheel_ki>
		<wheel_kd>0.0</wheel_kd>
	</plugin>
-->









    </model>
</sdf>